Workbook
Name Slicer_Broader_Category: #N/A
Name Slicer_Month: #N/A
Name Slicer_Sector: #N/A
Name Slicer_Year: #N/A

Sheet 01_Raw_Data
A1: Sector | B1: Year | C1: Month | D1: Cereals and products | E1: Meat and fish | F1: Egg | G1: Milk and products | H1: Oils and fats | I1: Fruits | J1: Vegetables | K1: Pulses and products | L1: Sugar and Confectionery | M1: Spices | N1: Non-alcoholic beverages | O1: Prepared meals, snacks, sweets etc. | P1: Food and beverages | Q1: Pan, tobacco and intoxicants | R1: Clothing | S1: Footwear | T1: Clothing and footwear | U1: Housing | V1: Fuel and light | W1: Household goods and services | X1: Health | Y1: Transport and communication | Z1: Recreation and amusement | AA1: Education | AB1: Personal care and effects | AC1: Miscellaneous | AD1: General index
A2: Rural | B2: 2013 | C2: January | D2: 107.5 | E2: 106.3 | F2: 108.1 | G2: 104.9 | H2: 106.1 | I2: 103.9 | J2: 101.9 | K2: 106.1 | L2: 106.8 | M2: 103.1 | N2: 104.8 | O2: 106.7 | P2: 105.5 | Q2: 105.1 | R2: 106.5 | S2: 105.8 | T2: 106.4 | U2: NA | V2: 105.5 | W2: 104.8 | X2: 104 | Y2: 103.3 | Z2: 103.4 | AA2: 103.8 | AB2: 104.7 | AC2: 104 | AD2: 105.1
A3: Urban | B3: 2013 | C3: January | D3: 110.5 | E3: 109.1 | F3: 113 | G3: 103.6 | H3: 103.4 | I3: 102.3 | J3: 102.9 | K3: 105.8 | L3: 105.1 | M3: 101.8 | N3: 105.1 | O3: 107.9 | P3: 105.9 | Q3: 105.2 | R3: 105.9 | S3: 105 | T3: 105.8 | U3: 100.3 | V3: 105.4 | W3: 104.8 | X3: 104.1 | Y3: 103.2 | Z3: 102.9 | AA3: 103.5 | AB3: 104.3 | AC3: 103.7 | AD3: 104
A4: Rural+Urban | B4: 2013 | C4: January | D4: 108.4 | E4: 107.3 | F4: 110 | G4: 104.4 | H4: 105.1 | I4: 103.2 | J4: 102.2 | K4: 106 | L4: 106.2 | M4: 102.7 | N4: 104.9 | O4: 107.3 | P4: 105.6 | Q4: 105.1 | R4: 106.3 | S4: 105.5 | T4: 106.2 | U4: 100.3 | V4: 105.5 | W4: 104.8 | X4: 104 | Y4: 103.2 | Z4: 103.1 | AA4: 103.6 | AB4: 104.5 | AC4: 103.9 | AD4: 104.6
A5: Rural | B5: 2013 | C5: February | D5: 109.2 | E5: 108.7 | F5: 110.2 | G5: 105.4 | H5: 106.7 | I5: 104 | J5: 102.4 | K5: 105.9 | L5: 105.7 | M5: 103.1 | N5: 105.1 | O5: 107.7 | P5: 106.3 | Q5: 105.6 | R5: 107.1 | S5: 106.3 | T5: 107 | U5: NA | V5: 106.2 | W5: 105.2 | X5: 104.4 | Y5: 103.9 | Z5: 104 | AA5: 104.1 | AB5: 104.6 | AC5: 104.4 | AD5: 105.8
A6: Urban | B6: 2013 | C6: February | D6: 112.9 | E6: 112.9 | F6: 116.9 | G6: 104 | H6: 103.5 | I6: 103.1 | J6: 104.9 | K6: 104.1 | L6: 103.8 | M6: 102.3 | N6: 106 | O6: 109 | P6: 107.2 | Q6: 106 | R6: 106.6 | S6: 105.5 | T6: 106.4 | U6: 100.4 | V6: 105.7 | W6: 105.2 | X6: 104.7 | Y6: 104.4 | Z6: 103.3 | AA6: 103.7 | AB6: 104.3 | AC6: 104.3 | AD6: 104.7
A7: Rural+Urban | B7: 2013 | C7: February | D7: 110.4 | E7: 110.2 | F7: 112.8 | G7: 104.9 | H7: 105.5 | I7: 103.6 | J7: 103.2 | K7: 105.3 | L7: 105.1 | M7: 102.8 | N7: 105.5 | O7: 108.3 | P7: 106.6 | Q7: 105.7 | R7: 106.9 | S7: 106 | T7: 106.8 | U7: 100.4 | V7: 106 | W7: 105.2 | X7: 104.5 | Y7: 104.2 | Z7: 103.6 | AA7: 103.9 | AB7: 104.5 | AC7: 104.4 | AD7: 105.3
A8: Rural | B8: 2013 | C8: March | D8: 110.2 | E8: 108.8 | F8: 109.9 | G8: 105.6 | H8: 106.2 | I8: 105.7 | J8: 101.4 | K8: 105.7 | L8: 105 | M8: 103.3 | N8: 105.6 | O8: 108.2 | P8: 106.6 | Q8: 106.5 | R8: 107.6 | S8: 106.8 | T8: 107.5 | U8: NA | V8: 106.1 | W8: 105.6 | X8: 104.7 | Y8: 104.6 | Z8: 104 | AA8: 104.3 | AB8: 104.3 | AC8: 104.6 | AD8: 106
A9: Urban | B9: 2013 | C9: March | D9: 113.9 | E9: 111.4 | F9: 113.2 | G9: 104.3 | H9: 102.7 | I9: 104.9 | J9: 103.8 | K9: 103.5 | L9: 102.6 | M9: 102.4 | N9: 107 | O9: 109.8 | P9: 107.3 | Q9: 106.8 | R9: 107.2 | S9: 106 | T9: 107 | U9: 100.4 | V9: 106 | W9: 105.7 | X9: 105.2 | Y9: 105.5 | Z9: 103.5 | AA9: 103.8 | AB9: 104.2 | AC9: 104.9 | AD9: 105
A10: Rural+Urban | B10: 2013 | C10: March | D10: 111.4 | E10: 109.7 | F10: 111.2 | G10: 105.1 | H10: 104.9 | I10: 105.3 | J10: 102.2 | K10: 105 | L10: 104.2 | M10: 103 | N10: 106.2 | O10: 108.9 | P10: 106.9 | Q10: 106.6 | R10: 107.4 | S10: 106.5 | T10: 107.3 | U10: 100.4 | V10: 106.1 | W10: 105.6 | X10: 104.9 | Y10: 105.1 | Z10: 103.7 | AA10: 104 | AB10: 104.3 | AC10: 104.7 | AD10: 105.5
A11: Rural | B11: 2013 | C11: April | D11: 110.2 | E11: 109.5 | F11: 106.9 | G11: 106.3 | H11: 105.7 | I11: 108.3 | J11: 103.4 | K11: 105.7 | L11: 104.2 | M11: 103.2 | N11: 106.5 | O11: 108.8 | P11: 107.1 | Q11: 107.1 | R11: 108.1 | S11: 107.4 | T11: 108 | U11: NA | V11: 106.5 | W11: 106.1 | X11: 105.1 | Y11: 104.4 | Z11: 104.5 | AA11: 104.8 | AB11: 102.7 | AC11: 104.6 | AD11: 106.4
A12: Urban | B12: 2013 | C12: April | D12: 114.6 | E12: 113.4 | F12: 106 | G12: 104.7 | H12: 102.1 | I12: 109.5 | J12: 109.7 | K12: 104.6 | L12: 102 | M12: 103.5 | N12: 108.2 | O12: 110.6 | P12: 108.8 | Q12: 108.5 | R12: 107.9 | S12: 106.4 | T12: 107.7 | U12: 100.5 | V12: 106.4 | W12: 106.5 | X12: 105.7 | Y12: 105 | Z12: 104 | AA12: 105.2 | AB12: 103.2 | AC12: 105.1 | AD12: 105.7
A13: Rural+Urban | B13: 2013 | C13: April | D13: 111.6 | E13: 110.9 | F13: 106.6 | G13: 105.7 | H13: 104.4 | I13: 108.9 | J13: 105.5 | K13: 105.3 | L13: 103.5 | M13: 103.3 | N13: 107.2 | O13: 109.6 | P13: 107.7 | Q13: 107.5 | R13: 108 | S13: 107 | T13: 107.9 | U13: 100.5 | V13: 106.5 | W13: 106.3 | X13: 105.3 | Y13: 104.7 | Z13: 104.2 | AA13: 105 | AB13: 102.9 | AC13: 104.8 | AD13: 106.1
A14: Rural | B14: 2013 | C14: May | D14: 110.9 | E14: 109.8 | F14: 105.9 | G14: 107.5 | H14: 105.3 | I14: 108.1 | J14: 107.3 | K14: 106.1 | L14: 103.7 | M14: 104 | N14: 107.4 | O14: 109.9 | P14: 108.1 | Q14: 108.1 | R14: 108.8 | S14: 107.9 | T14: 108.6 | U14: NA | V14: 107.5 | W14: 106.8 | X14: 105.7 | Y14: 104.1 | Z14: 105 | AA14: 105.5 | AB14: 102.1 | AC14: 104.8 | AD14: 107.2
A15: Urban | B15: 2013 | C15: May | D15: 115.4 | E15: 114.2 | F15: 102.7 | G15: 105.5 | H15: 101.5 | I15: 110.6 | J15: 123.7 | K15: 105.2 | L15: 101.9 | M15: 105 | N15: 109.1 | O15: 111.3 | P15: 111.1 | Q15: 109.8 | R15: 108.5 | S15: 106.7 | T15: 108.3 | U15: 100.5 | V15: 107.2 | W15: 107.1 | X15: 106.2 | Y15: 103.9 | Z15: 104.6 | AA15: 105.7 | AB15: 102.6 | AC15: 104.9 | AD15: 106.6
A16: Rural+Urban | B16: 2013 | C16: May | D16: 112.3 | E16: 111.3 | F16: 104.7 | G16: 106.8 | H16: 103.9 | I16: 109.3 | J16: 112.9 | K16: 105.8 | L16: 103.1 | M16: 104.3 | N16: 108.1 | O16: 110.5 | P16: 109.2 | Q16: 108.6 | R16: 108.7 | S16: 107.4 | T16: 108.5 | U16: 100.5 | V16: 107.4 | W16: 106.9 | X16: 105.9 | Y16: 104 | Z16: 104.8 | AA16: 105.6 | AB16: 102.3 | AC16: 104.8 | AD16: 106.9
A17: Rural | B17: 2013 | C17: June | D17: 112.3 | E17: 112.1 | F17: 108.1 | G17: 108.3 | H17: 105.9 | I17: 109.2 | J17: 118 | K17: 106.8 | L17: 104.1 | M17: 105.4 | N17: 108.2 | O17: 111 | P17: 110.6 | Q17: 109 | R17: 109.7 | S17: 108.8 | T17: 109.5 | U17: NA | V17: 108.5 | W17: 107.5 | X17: 106.3 | Y17: 105 | Z17: 105.6 | AA17: 106.5 | AB17: 102.5 | AC17: 105.5 | AD17: 108.9
A18: Urban | B18: 2013 | C18: June | D18: 117 | E18: 120.1 | F18: 112.5 | G18: 107.3 | H18: 101.3 | I18: 112.4 | J18: 143.6 | K18: 105.4 | L18: 101.4 | M18: 106.4 | N18: 110 | O18: 112.2 | P18: 115 | Q18: 110.9 | R18: 109.2 | S18: 107.2 | T18: 108.9 | U18: 106.6 | V18: 108 | W18: 107.7 | X18: 106.5 | Y18: 105.2 | Z18: 105.2 | AA18: 108.1 | AB18: 103.3 | AC18: 106.1 | AD18: 109.7
A19: Rural+Urban | B19: 2013 | C19: June | D19: 113.8 | E19: 114.9 | F19: 109.8 | G19: 107.9 | H19: 104.2 | I19: 110.7 | J19: 126.7 | K19: 106.3 | L19: 103.2 | M19: 105.7 | N19: 109 | O19: 111.6 | P19: 112.2 | Q19: 109.5 | R19: 109.5 | S19: 108.1 | T19: 109.3 | U19: 106.6 | V19: 108.3 | W19: 107.6 | X19: 106.4 | Y19: 105.1 | Z19: 105.4 | AA19: 107.4 | AB19: 102.8 | AC19: 105.8 | AD19: 109.3
A20: Rural | B20: 2013 | C20: July | D20: 113.4 | E20: 114.9 | F20: 110.5 | G20: 109.3 | H20: 106.2 | I20: 110.3 | J20: 129.2 | K20: 107.1 | L20: 104.3 | M20: 106.4 | N20: 109.1 | O20: 112.1 | P20: 113.1 | Q20: 109.8 | R20: 110.5 | S20: 109.5 | T20: 110.3 | U20: NA | V20: 109.5 | W20: 108.3 | X20: 106.9 | Y20: 106.8 | Z20: 106.4 | AA20: 107.8 | AB20: 102.5 | AC20: 106.5 | AD20: 110.7
A21: Urban | B21: 2013 | C21: July | D21: 117.8 | E21: 119.2 | F21: 114 | G21: 108.3 | H21: 101.1 | I21: 113.2 | J21: 160.9 | K21: 105.1 | L21: 101.3 | M21: 107.5 | N21: 110.4 | O21: 113.1 | P21: 117.5 | Q21: 111.7 | R21: 109.8 | S21: 107.8 | T21: 109.5 | U21: 107.7 | V21: 108.6 | W21: 108.1 | X21: 107.1 | Y21: 107.3 | Z21: 105.9 | AA21: 110.1 | AB21: 103.2 | AC21: 107.3 | AD21: 111.4
A22: Rural+Urban | B22: 2013 | C22: July | D22: 114.8 | E22: 116.4 | F22: 111.9 | G22: 108.9 | H22: 104.3 | I22: 111.7 | J22: 140 | K22: 106.4 | L22: 103.3 | M22: 106.8 | N22: 109.6 | O22: 112.6 | P22: 114.7 | Q22: 110.3 | R22: 110.2 | S22: 108.8 | T22: 110 | U22: 107.7 | V22: 109.2 | W22: 108.2 | X22: 107 | Y22: 107.1 | Z22: 106.1 | AA22: 109.1 | AB22: 102.8 | AC22: 106.9 | AD22: 111
A23: Rural | B23: 2013 | C23: August | D23: 114.3 | E23: 115.4 | F23: 111.1 | G23: 110 | H23: 106.4 | I23: 110.8 | J23: 138.9 | K23: 107.4 | L23: 104.1 | M23: 106.9 | N23: 109.7 | O23: 112.6 | P23: 114.9 | Q23: 110.7 | R23: 111.3 | S23: 110.2 | T23: 111.1 | U23: NA | V23: 109.9 | W23: 108.7 | X23: 107.5 | Y23: 107.8 | Z23: 106.8 | AA23: 108.7 | AB23: 105 | AC23: 107.5 | AD23: 112.1
A24: Urban | B24: 2013 | C24: August | D24: 118.3 | E24: 120.4 | F24: 112.7 | G24: 108.9 | H24: 101.1 | I24: 108.7 | J24: 177 | K24: 104.7 | L24: 101 | M24: 108.5 | N24: 110.9 | O24: 114.3 | P24: 119.6 | Q24: 112.4 | R24: 110.6 | S24: 108.3 | T24: 110.2 | U24: 108.9 | V24: 109.3 | W24: 108.7 | X24: 107.6 | Y24: 108.1 | Z24: 106.5 | AA24: 110.8 | AB24: 106 | AC24: 108.3 | AD24: 112.7
A25: Rural+Urban | B25: 2013 | C25: August | D25: 115.6 | E25: 117.2 | F25: 111.7 | G25: 109.6 | H25: 104.5 | I25: 109.8 | J25: 151.8 | K25: 106.5 | L25: 103.1 | M25: 107.4 | N25: 110.2 | O25: 113.4 | P25: 116.6 | Q25: 111.2 | R25: 111 | S25: 109.4 | T25: 110.7 | U25: 108.9 | V25: 109.7 | W25: 108.7 | X25: 107.5 | Y25: 108 | Z25: 106.6 | AA25: 109.9 | AB25: 105.4 | AC25: 107.9 | AD25: 112.4
A26: Rural | B26: 2013 | C26: September | D26: 115.4 | E26: 115.7 | F26: 111.7 | G26: 111 | H26: 107.4 | I26: 110.9 | J26: 154 | K26: 108.1 | L26: 104.2 | M26: 107.9 | N26: 110.4 | O26: 114 | P26: 117.8 | Q26: 111.7 | R26: 112.7 | S26: 111.4 | T26: 112.5 | U26: NA | V26: 111.1 | W26: 109.6 | X26: 108.3 | Y26: 109.3 | Z26: 107.7 | AA26: 109.8 | AB26: 106.7 | AC26: 108.7 | AD26: 114.2
A27: Urban | B27: 2013 | C27: September | D27: 118.6 | E27: 119.1 | F27: 113.2 | G27: 109.6 | H27: 101.7 | I27: 103.2 | J27: 174.3 | K27: 105.1 | L27: 100.8 | M27: 109.1 | N27: 111.1 | O27: 115.4 | P27: 119.2 | Q27: 112.9 | R27: 111.4 | S27: 109 | T27: 111.1 | U27: 109.7 | V27: 109.5 | W27: 109.6 | X27: 107.9 | Y27: 110.4 | Z27: 107.4 | AA27: 111.2 | AB27: 106.9 | AC27: 109.4 | AD27: 113.2
A28: Rural+Urban | B28: 2013 | C28: September | D28: 116.4 | E28: 116.9 | F28: 112.3 | G28: 110.5 | H28: 105.3 | I28: 107.3 | J28: 160.9 | K28: 107.1 | L28: 103.1 | M28: 108.3 | N28: 110.7 | O28: 114.6 | P28: 118.3 | Q28: 112 | R28: 112.2 | S28: 110.4 | T28: 111.9 | U28: 109.7 | V28: 110.5 | W28: 109.6 | X28: 108.1 | Y28: 109.9 | Z28: 107.5 | AA28: 110.6 | AB28: 106.8 | AC28: 109 | AD28: 113.7
A29: Rural | B29: 2013 | C29: October | D29: 116.3 | E29: 115.4 | F29: 112.6 | G29: 111.7 | H29: 107.7 | I29: 113.2 | J29: 164.9 | K29: 108.3 | L29: 103.9 | M29: 108.2 | N29: 111.1 | O29: 114.9 | P29: 119.8 | Q29: 112.2 | R29: 113.6 | S29: 112.3 | T29: 113.4 | U29: NA | V29: 111.6 | W29: 110.4 | X29: 108.9 | Y29: 109.3 | Z29: 108.3 | AA29: 110.2 | AB29: 107.5 | AC29: 109.1 | AD29: 115.5
A30: Urban | B30: 2013 | C30: October | D30: 118.9 | E30: 118.1 | F30: 114.5 | G30: 110.4 | H30: 102.3 | I30: 106.2 | J30: 183.5 | K30: 105.3 | L30: 100.2 | M30: 109.6 | N30: 111.4 | O30: 116 | P30: 120.8 | Q30: 113.5 | R30: 112.5 | S30: 109.7 | T30: 112 | U30: 110.5 | V30: 109.7 | W30: 110.2 | X30: 108.2 | Y30: 109.7 | Z30: 108 | AA30: 111.3 | AB30: 107.3 | AC30: 109.4 | AD30: 114
A31: Rural+Urban | B31: 2013 | C31: October | D31: 117.1 | E31: 116.3 | F31: 113.3 | G31: 111.2 | H31: 105.7 | I31: 109.9 | J31: 171.2 | K31: 107.3 | L31: 102.7 | M31: 108.7 | N31: 111.2 | O31: 115.4 | P31: 120.2 | Q31: 112.5 | R31: 113.2 | S31: 111.2 | T31: 112.8 | U31: 110.5 | V31: 110.9 | W31: 110.3 | X31: 108.6 | Y31: 109.5 | Z31: 108.1 | AA31: 110.8 | AB31: 107.4 | AC31: 109.2 | AD31: 114.8
A32: Rural | B32: 2013 | C32: November | D32: 117.3 | E32: 114.9 | F32: 116.2 | G32: 112.8 | H32: 108.9 | I32: 116.6 | J32: 178.1 | K32: 109.1 | L32: 103.6 | M32: 109 | N32: 111.8 | O32: 116 | P32: 122.5 | Q32: 112.8 | R32: 114.6 | S32: 113.1 | T32: 114.4 | U32: NA | V32: 112.6 | W32: 111.3 | X32: 109.7 | Y32: 109.6 | Z32: 108.7 | AA32: 111 | AB32: 108.2 | AC32: 109.8 | AD32: 117.4
A33: Urban | B33: 2013 | C33: November | D33: 119.8 | E33: 116.3 | F33: 122.6 | G33: 112 | H33: 103.2 | I33: 110 | J33: 192.8 | K33: 106.3 | L33: 99.5 | M33: 110.3 | N33: 111.8 | O33: 117.1 | P33: 122.9 | Q33: 114.1 | R33: 113.5 | S33: 110.3 | T33: 113 | U33: 111.1 | V33: 110 | W33: 110.9 | X33: 108.6 | Y33: 109.5 | Z33: 108.5 | AA33: 111.3 | AB33: 107.9 | AC33: 109.6 | AD33: 115
A34: Rural+Urban | B34: 2013 | C34: November | D34: 118.1 | E34: 115.4 | F34: 118.7 | G34: 112.5 | H34: 106.8 | I34: 113.5 | J34: 183.1 | K34: 108.2 | L34: 102.2 | M34: 109.4 | N34: 111.8 | O34: 116.5 | P34: 122.6 | Q34: 113.1 | R34: 114.2 | S34: 111.9 | T34: 113.8 | U34: 111.1 | V34: 111.6 | W34: 111.1 | X34: 109.3 | Y34: 109.5 | Z34: 108.6 | AA34: 111.2 | AB34: 108.1 | AC34: 109.7 | AD34: 116.3
A35: Rural | B35: 2013 | C35: December | D35: 118.4 | E35: 115.9 | F35: 120.4 | G35: 113.8 | H35: 109.5 | I35: 115.5 | J35: 145.7 | K35: 109.5 | L35: 102.9 | M35: 109.8 | N35: 112.1 | O35: 116.8 | P35: 118.7 | Q35: 113.6 | R35: 115.8 | S35: 114 | T35: 115.5 | U35: NA | V35: 112.8 | W35: 112.1 | X35: 110.1 | Y35: 109.9 | Z35: 109.2 | AA35: 111.6 | AB35: 108.1 | AC35: 110.1 | AD35: 115.5
A36: Urban | B36: 2013 | C36: December | D36: 120.5 | E36: 118.1 | F36: 128.5 | G36: 112.8 | H36: 103.4 | I36: 110.7 | J36: 144.8 | K36: 107.1 | L36: 98.6 | M36: 111.9 | N36: 112.1 | O36: 118.1 | P36: 117.8 | Q36: 115 | R36: 114.2 | S36: 110.9 | T36: 113.7 | U36: 110.7 | V36: 110.4 | W36: 111.3 | X36: 109 | Y36: 109.7 | Z36: 108.9 | AA36: 111.4 | AB36: 107.7 | AC36: 109.8 | AD36: 113.3
A37: Rural+Urban | B37: 2013 | C37: December | D37: 119.1 | E37: 116.7 | F37: 123.5 | G37: 113.4 | H37: 107.3 | I37: 113.3 | J37: 145.4 | K37: 108.7 | L37: 101.5 | M37: 110.5 | N37: 112.1 | O37: 117.4 | P37: 118.4 | Q37: 114 | R37: 115.2 | S37: 112.7 | T37: 114.8 | U37: 110.7 | V37: 111.9 | W37: 111.7 | X37: 109.7 | Y37: 109.8 | Z37: 109 | AA37: 111.5 | AB37: 107.9 | AC37: 110 | AD37: 114.5
A38: Rural | B38: 2014 | C38: January | D38: 118.9 | E38: 117.1 | F38: 120.5 | G38: 114.4 | H38: 109 | I38: 115.5 | J38: 123.9 | K38: 109.6 | L38: 101.8 | M38: 110.2 | N38: 112.4 | O38: 117.3 | P38: 116 | Q38: 114 | R38: 116.5 | S38: 114.5 | T38: 116.2 | U38: NA | V38: 113 | W38: 112.6 | X38: 110.6 | Y38: 110.5 | Z38: 109.6 | AA38: 111.8 | AB38: 108.3 | AC38: 110.6 | AD38: 114.2
A39: Urban | B39: 2014 | C39: January | D39: 121.2 | E39: 122 | F39: 129.9 | G39: 113.6 | H39: 102.9 | I39: 112.1 | J39: 118.9 | K39: 107.5 | L39: 96.9 | M39: 112.7 | N39: 112.1 | O39: 119 | P39: 115.5 | Q39: 115.7 | R39: 114.8 | S39: 111.3 | T39: 114.3 | U39: 111.6 | V39: 111 | W39: 111.9 | X39: 109.7 | Y39: 110.8 | Z39: 109.8 | AA39: 111.5 | AB39: 108 | AC39: 110.5 | AD39: 112.9
A40: Rural+Urban | B40: 2014 | C40: January | D40: 119.6 | E40: 118.8 | F40: 124.1 | G40: 114.1 | H40: 106.8 | I40: 113.9 | J40: 122.2 | K40: 108.9 | L40: 100.2 | M40: 111 | N40: 112.3 | O40: 118.1 | P40: 115.8 | Q40: 114.5 | R40: 115.8 | S40: 113.2 | T40: 115.4 | U40: 111.6 | V40: 112.2 | W40: 112.3 | X40: 110.3 | Y40: 110.7 | Z40: 109.7 | AA40: 111.6 | AB40: 108.2 | AC40: 110.6 | AD40: 113.6
...

Sheet 02_Clean_Data
A1: Sector | B1: Year | C1: Month | D1: Cereals and products | E1: Meat and fish | F1: Egg | G1: Milk and products | H1: Oils and fats | I1: Fruits | J1: Vegetables | K1: Pulses and products | L1: Sugar and Confectionery | M1: Spices | N1: Non-alcoholic beverages | O1: Prepared meals, snacks, sweets etc. | P1: Food and beverages | Q1: Pan, tobacco and intoxicants | R1: Clothing | S1: Footwear | T1: Clothing and footwear | U1: Housing | V1: Fuel and light | W1: Household goods and services | X1: Health | Y1: Transport and communication | Z1: Recreation and amusement | AA1: Education | AB1: Personal care and effects | AC1: Miscellaneous | AD1: General index | AE1: Unique ID | AF1: Date
A2: Rural | B2: 2013 | C2: January | D2: 107.5 | E2: 106.3 | F2: 108.1 | G2: 104.9 | H2: 106.1 | I2: 103.9 | J2: 101.9 | K2: 106.1 | L2: 106.8 | M2: 103.1 | N2: 104.8 | O2: 106.7 | P2: 105.5 | Q2: 105.1 | R2: 106.5 | S2: 105.8 | T2: 106.4 | U2: NA | V2: 105.5 | W2: 104.8 | X2: 104 | Y2: 103.3 | Z2: 103.4 | AA2: 103.8 | AB2: 104.7 | AC2: 104 | AD2: 105.1 | AE2: =tbl_CPI_Clean[[#This Row],[Sector]]&"_"&tbl_CPI_Clean[[#This Row],[Year]]&"_"&tbl_CPI_Clean[[#This Row],[Month]] -> Rural_2013_January | AF2: =DATE(tbl_CPI_Clean[[#This Row],[Year]],MATCH(tbl_CPI_Clean[[#This Row],[Month]],{"January","February","March","April","May","June","July","August","September","October","November","December"},0),1) -> 41275
A3: Urban | B3: 2013 | C3: January | D3: 110.5 | E3: 109.1 | F3: 113 | G3: 103.6 | H3: 103.4 | I3: 102.3 | J3: 102.9 | K3: 105.8 | L3: 105.1 | M3: 101.8 | N3: 105.1 | O3: 107.9 | P3: 105.9 | Q3: 105.2 | R3: 105.9 | S3: 105 | T3: 105.8 | U3: 100.3 | V3: 105.4 | W3: 104.8 | X3: 104.1 | Y3: 103.2 | Z3: 102.9 | AA3: 103.5 | AB3: 104.3 | AC3: 103.7 | AD3: 104 | AE3: =tbl_CPI_Clean[[#This Row],[Sector]]&"_"&tbl_CPI_Clean[[#This Row],[Year]]&"_"&tbl_CPI_Clean[[#This Row],[Month]] -> Urban_2013_January | AF3: =DATE(tbl_CPI_Clean[[#This Row],[Year]],MATCH(tbl_CPI_Clean[[#This Row],[Month]],{"January","February","March","April","May","June","July","August","September","October","November","December"},0),1) -> 41275
A4: Rural+Urban | B4: 2013 | C4: January | D4: 108.4 | E4: 107.3 | F4: 110 | G4: 104.4 | H4: 105.1 | I4: 103.2 | J4: 102.2 | K4: 106 | L4: 106.2 | M4: 102.7 | N4: 104.9 | O4: 107.3 | P4: 105.6 | Q4: 105.1 | R4: 106.3 | S4: 105.5 | T4: 106.2 | U4: 100.3 | V4: 105.5 | W4: 104.8 | X4: 104 | Y4: 103.2 | Z4: 103.1 | AA4: 103.6 | AB4: 104.5 | AC4: 103.9 | AD4: 104.6 | AE4: =tbl_CPI_Clean[[#This Row],[Sector]]&"_"&tbl_CPI_Clean[[#This Row],[Year]]&"_"&tbl_CPI_Clean[[#This Row],[Month]] -> Rural+Urban_2013_January | AF4: =DATE(tbl_CPI_Clean[[#This Row],[Year]],MATCH(tbl_CPI_Clean[[#This Row],[Month]],{"January","February","March","April","May","June","July","August","September","October","November","December"},0),1) -> 41275
A5: Rural | B5: 2013 | C5: February | D5: 109.2 | E5: 108.7 | F5: 110.2 | G5: 105.4 | H5: 106.7 | I5: 104 | J5: 102.4 | K5: 105.9 | L5: 105.7 | M5: 103.1 | N5: 105.1 | O5: 107.7 | P5: 106.3 | Q5: 105.6 | R5: 107.1 | S5: 106.3 | T5: 107 | U5: NA | V5: 106.2 | W5: 105.2 | X5: 104.4 | Y5: 103.9 | Z5: 104 | AA5: 104.1 | AB5: 104.6 | AC5: 104.4 | AD5: 105.8 | AE5: =tbl_CPI_Clean[[#This Row],[Sector]]&"_"&tbl_CPI_Clean[[#This Row],[Year]]&"_"&tbl_CPI_Clean[[#This Row],[Month]] -> Rural_2013_February | AF5: =DATE(tbl_CPI_Clean[[#This Row],[Year]],MATCH(tbl_CPI_Clean[[#This Row],[Month]],{"January","February","March","April","May","June","July","August","September","October","November","December"},0),1) -> 41306
A6: Urban | B6: 2013 | C6: February | D6: 112.9 | E6: 112.9 | F6: 116.9 | G6: 104 | H6: 103.5 | I6: 103.1 | J6: 104.9 | K6: 104.1 | L6: 103.8 | M6: 102.3 | N6: 106 | O6: 109 | P6: 107.2 | Q6: 106 | R6: 106.6 | S6: 105.5 | T6: 106.4 | U6: 100.4 | V6: 105.7 | W6: 105.2 | X6: 104.7 | Y6: 104.4 | Z6: 103.3 | AA6: 103.7 | AB6: 104.3 | AC6: 104.3 | AD6: 104.7 | AE6: =tbl_CPI_Clean[[#This Row],[Sector]]&"_"&tbl_CPI_Clean[[#This Row],[Year]]&"_"&tbl_CPI_Clean[[#This Row],[Month]] -> Urban_2013_February | AF6: =DATE(tbl_CPI_Clean[[#This Row],[Year]],MATCH(tbl_CPI_Clean[[#This Row],[Month]],{"January","February","March","April","May","June","July","August","September","October","November","December"},0),1) -> 41306
A7: Rural+Urban | B7: 2013 | C7: February | D7: 110.4 | E7: 110.2 | F7: 112.8 | G7: 104.9 | H7: 105.5 | I7: 103.6 | J7: 103.2 | K7: 105.3 | L7: 105.1 | M7: 102.8 | N7: 105.5 | O7: 108.3 | P7: 106.6 | Q7: 105.7 | R7: 106.9 | S7: 106 | T7: 106.8 | U7: 100.4 | V7: 106 | W7: 105.2 | X7: 104.5 | Y7: 104.2 | Z7: 103.6 | AA7: 103.9 | AB7: 104.5 | AC7: 104.4 | AD7: 105.3 | AE7: =tbl_CPI_Clean[[#This Row],[Sector]]&"_"&tbl_CPI_Clean[[#This Row],[Year]]&"_"&tbl_CPI_Clean[[#This Row],[Month]] -> Rural+Urban_2013_February | AF7: =DATE(tbl_CPI_Clean[[#This Row],[Year]],MATCH(tbl_CPI_Clean[[#This Row],[Month]],{"January","February","March","April","May","June","July","August","September","October","November","December"},0),1) -> 41306
A8: Rural | B8: 2013 | C8: March | D8: 110.2 | E8: 108.8 | F8: 109.9 | G8: 105.6 | H8: 106.2 | I8: 105.7 | J8: 101.4 | K8: 105.7 | L8: 105 | M8: 103.3 | N8: 105.6 | O8: 108.2 | P8: 106.6 | Q8: 106.5 | R8: 107.6 | S8: 106.8 | T8: 107.5 | U8: NA | V8: 106.1 | W8: 105.6 | X8: 104.7 | Y8: 104.6 | Z8: 104 | AA8: 104.3 | AB8: 104.3 | AC8: 104.6 | AD8: 106 | AE8: =tbl_CPI_Clean[[#This Row],[Sector]]&"_"&tbl_CPI_Clean[[#This Row],[Year]]&"_"&tbl_CPI_Clean[[#This Row],[Month]] -> Rural_2013_March | AF8: =DATE(tbl_CPI_Clean[[#This Row],[Year]],MATCH(tbl_CPI_Clean[[#This Row],[Month]],{"January","February","March","April","May","June","July","August","September","October","November","December"},0),1) -> 41334 | AI8: Row Labels | AJ8: Count of General index
A9: Urban | B9: 2013 | C9: March | D9: 113.9 | E9: 111.4 | F9: 113.2 | G9: 104.3 | H9: 102.7 | I9: 104.9 | J9: 103.8 | K9: 103.5 | L9: 102.6 | M9: 102.4 | N9: 107 | O9: 109.8 | P9: 107.3 | Q9: 106.8 | R9: 107.2 | S9: 106 | T9: 107 | U9: 100.4 | V9: 106 | W9: 105.7 | X9: 105.2 | Y9: 105.5 | Z9: 103.5 | AA9: 103.8 | AB9: 104.2 | AC9: 104.9 | AD9: 105 | AE9: =tbl_CPI_Clean[[#This Row],[Sector]]&"_"&tbl_CPI_Clean[[#This Row],[Year]]&"_"&tbl_CPI_Clean[[#This Row],[Month]] -> Urban_2013_March | AF9: =DATE(tbl_CPI_Clean[[#This Row],[Year]],MATCH(tbl_CPI_Clean[[#This Row],[Month]],{"January","February","March","April","May","June","July","August","September","October","November","December"},0),1) -> 41334 | AI9: Rural | AJ9: 124
A10: Rural+Urban | B10: 2013 | C10: March | D10: 111.4 | E10: 109.7 | F10: 111.2 | G10: 105.1 | H10: 104.9 | I10: 105.3 | J10: 102.2 | K10: 105 | L10: 104.2 | M10: 103 | N10: 106.2 | O10: 108.9 | P10: 106.9 | Q10: 106.6 | R10: 107.4 | S10: 106.5 | T10: 107.3 | U10: 100.4 | V10: 106.1 | W10: 105.6 | X10: 104.9 | Y10: 105.1 | Z10: 103.7 | AA10: 104 | AB10: 104.3 | AC10: 104.7 | AD10: 105.5 | AE10: =tbl_CPI_Clean[[#This Row],[Sector]]&"_"&tbl_CPI_Clean[[#This Row],[Year]]&"_"&tbl_CPI_Clean[[#This Row],[Month]] -> Rural+Urban_2013_March | AF10: =DATE(tbl_CPI_Clean[[#This Row],[Year]],MATCH(tbl_CPI_Clean[[#This Row],[Month]],{"January","February","March","April","May","June","July","August","September","October","November","December"},0),1) -> 41334 | AI10: Rural+Urban | AJ10: 124
A11: Rural | B11: 2013 | C11: April | D11: 110.2 | E11: 109.5 | F11: 106.9 | G11: 106.3 | H11: 105.7 | I11: 108.3 | J11: 103.4 | K11: 105.7 | L11: 104.2 | M11: 103.2 | N11: 106.5 | O11: 108.8 | P11: 107.1 | Q11: 107.1 | R11: 108.1 | S11: 107.4 | T11: 108 | U11: NA | V11: 106.5 | W11: 106.1 | X11: 105.1 | Y11: 104.4 | Z11: 104.5 | AA11: 104.8 | AB11: 102.7 | AC11: 104.6 | AD11: 106.4 | AE11: =tbl_CPI_Clean[[#This Row],[Sector]]&"_"&tbl_CPI_Clean[[#This Row],[Year]]&"_"&tbl_CPI_Clean[[#This Row],[Month]] -> Rural_2013_April | AF11: =DATE(tbl_CPI_Clean[[#This Row],[Year]],MATCH(tbl_CPI_Clean[[#This Row],[Month]],{"January","February","March","April","May","June","July","August","September","October","November","December"},0),1) -> 41365 | AI11: Urban | AJ11: 124
A12: Urban | B12: 2013 | C12: April | D12: 114.6 | E12: 113.4 | F12: 106 | G12: 104.7 | H12: 102.1 | I12: 109.5 | J12: 109.7 | K12: 104.6 | L12: 102 | M12: 103.5 | N12: 108.2 | O12: 110.6 | P12: 108.8 | Q12: 108.5 | R12: 107.9 | S12: 106.4 | T12: 107.7 | U12: 100.5 | V12: 106.4 | W12: 106.5 | X12: 105.7 | Y12: 105 | Z12: 104 | AA12: 105.2 | AB12: 103.2 | AC12: 105.1 | AD12: 105.7 | AE12: =tbl_CPI_Clean[[#This Row],[Sector]]&"_"&tbl_CPI_Clean[[#This Row],[Year]]&"_"&tbl_CPI_Clean[[#This Row],[Month]] -> Urban_2013_April | AF12: =DATE(tbl_CPI_Clean[[#This Row],[Year]],MATCH(tbl_CPI_Clean[[#This Row],[Month]],{"January","February","March","April","May","June","July","August","September","October","November","December"},0),1) -> 41365 | AI12: Grand Total | AJ12: 372
A13: Rural+Urban | B13: 2013 | C13: April | D13: 111.6 | E13: 110.9 | F13: 106.6 | G13: 105.7 | H13: 104.4 | I13: 108.9 | J13: 105.5 | K13: 105.3 | L13: 103.5 | M13: 103.3 | N13: 107.2 | O13: 109.6 | P13: 107.7 | Q13: 107.5 | R13: 108 | S13: 107 | T13: 107.9 | U13: 100.5 | V13: 106.5 | W13: 106.3 | X13: 105.3 | Y13: 104.7 | Z13: 104.2 | AA13: 105 | AB13: 102.9 | AC13: 104.8 | AD13: 106.1 | AE13: =tbl_CPI_Clean[[#This Row],[Sector]]&"_"&tbl_CPI_Clean[[#This Row],[Year]]&"_"&tbl_CPI_Clean[[#This Row],[Month]] -> Rural+Urban_2013_April | AF13: =DATE(tbl_CPI_Clean[[#This Row],[Year]],MATCH(tbl_CPI_Clean[[#This Row],[Month]],{"January","February","March","April","May","June","July","August","September","October","November","December"},0),1) -> 41365
A14: Rural | B14: 2013 | C14: May | D14: 110.9 | E14: 109.8 | F14: 105.9 | G14: 107.5 | H14: 105.3 | I14: 108.1 | J14: 107.3 | K14: 106.1 | L14: 103.7 | M14: 104 | N14: 107.4 | O14: 109.9 | P14: 108.1 | Q14: 108.1 | R14: 108.8 | S14: 107.9 | T14: 108.6 | U14: NA | V14: 107.5 | W14: 106.8 | X14: 105.7 | Y14: 104.1 | Z14: 105 | AA14: 105.5 | AB14: 102.1 | AC14: 104.8 | AD14: 107.2 | AE14: =tbl_CPI_Clean[[#This Row],[Sector]]&"_"&tbl_CPI_Clean[[#This Row],[Year]]&"_"&tbl_CPI_Clean[[#This Row],[Month]] -> Rural_2013_May | AF14: =DATE(tbl_CPI_Clean[[#This Row],[Year]],MATCH(tbl_CPI_Clean[[#This Row],[Month]],{"January","February","March","April","May","June","July","August","September","October","November","December"},0),1) -> 41395
A15: Urban | B15: 2013 | C15: May | D15: 115.4 | E15: 114.2 | F15: 102.7 | G15: 105.5 | H15: 101.5 | I15: 110.6 | J15: 123.7 | K15: 105.2 | L15: 101.9 | M15: 105 | N15: 109.1 | O15: 111.3 | P15: 111.1 | Q15: 109.8 | R15: 108.5 | S15: 106.7 | T15: 108.3 | U15: 100.5 | V15: 107.2 | W15: 107.1 | X15: 106.2 | Y15: 103.9 | Z15: 104.6 | AA15: 105.7 | AB15: 102.6 | AC15: 104.9 | AD15: 106.6 | AE15: =tbl_CPI_Clean[[#This Row],[Sector]]&"_"&tbl_CPI_Clean[[#This Row],[Year]]&"_"&tbl_CPI_Clean[[#This Row],[Month]] -> Urban_2013_May | AF15: =DATE(tbl_CPI_Clean[[#This Row],[Year]],MATCH(tbl_CPI_Clean[[#This Row],[Month]],{"January","February","March","April","May","June","July","August","September","October","November","December"},0),1) -> 41395
A16: Rural+Urban | B16: 2013 | C16: May | D16: 112.3 | E16: 111.3 | F16: 104.7 | G16: 106.8 | H16: 103.9 | I16: 109.3 | J16: 112.9 | K16: 105.8 | L16: 103.1 | M16: 104.3 | N16: 108.1 | O16: 110.5 | P16: 109.2 | Q16: 108.6 | R16: 108.7 | S16: 107.4 | T16: 108.5 | U16: 100.5 | V16: 107.4 | W16: 106.9 | X16: 105.9 | Y16: 104 | Z16: 104.8 | AA16: 105.6 | AB16: 102.3 | AC16: 104.8 | AD16: 106.9 | AE16: =tbl_CPI_Clean[[#This Row],[Sector]]&"_"&tbl_CPI_Clean[[#This Row],[Year]]&"_"&tbl_CPI_Clean[[#This Row],[Month]] -> Rural+Urban_2013_May | AF16: =DATE(tbl_CPI_Clean[[#This Row],[Year]],MATCH(tbl_CPI_Clean[[#This Row],[Month]],{"January","February","March","April","May","June","July","August","September","October","November","December"},0),1) -> 41395
A17: Rural | B17: 2013 | C17: June | D17: 112.3 | E17: 112.1 | F17: 108.1 | G17: 108.3 | H17: 105.9 | I17: 109.2 | J17: 118 | K17: 106.8 | L17: 104.1 | M17: 105.4 | N17: 108.2 | O17: 111 | P17: 110.6 | Q17: 109 | R17: 109.7 | S17: 108.8 | T17: 109.5 | U17: NA | V17: 108.5 | W17: 107.5 | X17: 106.3 | Y17: 105 | Z17: 105.6 | AA17: 106.5 | AB17: 102.5 | AC17: 105.5 | AD17: 108.9 | AE17: =tbl_CPI_Clean[[#This Row],[Sector]]&"_"&tbl_CPI_Clean[[#This Row],[Year]]&"_"&tbl_CPI_Clean[[#This Row],[Month]] -> Rural_2013_June | AF17: =DATE(tbl_CPI_Clean[[#This Row],[Year]],MATCH(tbl_CPI_Clean[[#This Row],[Month]],{"January","February","March","April","May","June","July","August","September","October","November","December"},0),1) -> 41426
A18: Urban | B18: 2013 | C18: June | D18: 117 | E18: 120.1 | F18: 112.5 | G18: 107.3 | H18: 101.3 | I18: 112.4 | J18: 143.6 | K18: 105.4 | L18: 101.4 | M18: 106.4 | N18: 110 | O18: 112.2 | P18: 115 | Q18: 110.9 | R18: 109.2 | S18: 107.2 | T18: 108.9 | U18: 106.6 | V18: 108 | W18: 107.7 | X18: 106.5 | Y18: 105.2 | Z18: 105.2 | AA18: 108.1 | AB18: 103.3 | AC18: 106.1 | AD18: 109.7 | AE18: =tbl_CPI_Clean[[#This Row],[Sector]]&"_"&tbl_CPI_Clean[[#This Row],[Year]]&"_"&tbl_CPI_Clean[[#This Row],[Month]] -> Urban_2013_June | AF18: =DATE(tbl_CPI_Clean[[#This Row],[Year]],MATCH(tbl_CPI_Clean[[#This Row],[Month]],{"January","February","March","April","May","June","July","August","September","October","November","December"},0),1) -> 41426
A19: Rural+Urban | B19: 2013 | C19: June | D19: 113.8 | E19: 114.9 | F19: 109.8 | G19: 107.9 | H19: 104.2 | I19: 110.7 | J19: 126.7 | K19: 106.3 | L19: 103.2 | M19: 105.7 | N19: 109 | O19: 111.6 | P19: 112.2 | Q19: 109.5 | R19: 109.5 | S19: 108.1 | T19: 109.3 | U19: 106.6 | V19: 108.3 | W19: 107.6 | X19: 106.4 | Y19: 105.1 | Z19: 105.4 | AA19: 107.4 | AB19: 102.8 | AC19: 105.8 | AD19: 109.3 | AE19: =tbl_CPI_Clean[[#This Row],[Sector]]&"_"&tbl_CPI_Clean[[#This Row],[Year]]&"_"&tbl_CPI_Clean[[#This Row],[Month]] -> Rural+Urban_2013_June | AF19: =DATE(tbl_CPI_Clean[[#This Row],[Year]],MATCH(tbl_CPI_Clean[[#This Row],[Month]],{"January","February","March","April","May","June","July","August","September","October","November","December"},0),1) -> 41426
A20: Rural | B20: 2013 | C20: July | D20: 113.4 | E20: 114.9 | F20: 110.5 | G20: 109.3 | H20: 106.2 | I20: 110.3 | J20: 129.2 | K20: 107.1 | L20: 104.3 | M20: 106.4 | N20: 109.1 | O20: 112.1 | P20: 113.1 | Q20: 109.8 | R20: 110.5 | S20: 109.5 | T20: 110.3 | U20: NA | V20: 109.5 | W20: 108.3 | X20: 106.9 | Y20: 106.8 | Z20: 106.4 | AA20: 107.8 | AB20: 102.5 | AC20: 106.5 | AD20: 110.7 | AE20: =tbl_CPI_Clean[[#This Row],[Sector]]&"_"&tbl_CPI_Clean[[#This Row],[Year]]&"_"&tbl_CPI_Clean[[#This Row],[Month]] -> Rural_2013_July | AF20: =DATE(tbl_CPI_Clean[[#This Row],[Year]],MATCH(tbl_CPI_Clean[[#This Row],[Month]],{"January","February","March","April","May","June","July","August","September","October","November","December"},0),1) -> 41456
A21: Urban | B21: 2013 | C21: July | D21: 117.8 | E21: 119.2 | F21: 114 | G21: 108.3 | H21: 101.1 | I21: 113.2 | J21: 160.9 | K21: 105.1 | L21: 101.3 | M21: 107.5 | N21: 110.4 | O21: 113.1 | P21: 117.5 | Q21: 111.7 | R21: 109.8 | S21: 107.8 | T21: 109.5 | U21: 107.7 | V21: 108.6 | W21: 108.1 | X21: 107.1 | Y21: 107.3 | Z21: 105.9 | AA21: 110.1 | AB21: 103.2 | AC21: 107.3 | AD21: 111.4 | AE21: =tbl_CPI_Clean[[#This Row],[Sector]]&"_"&tbl_CPI_Clean[[#This Row],[Year]]&"_"&tbl_CPI_Clean[[#This Row],[Month]] -> Urban_2013_July | AF21: =DATE(tbl_CPI_Clean[[#This Row],[Year]],MATCH(tbl_CPI_Clean[[#This Row],[Month]],{"January","February","March","April","May","June","July","August","September","October","November","December"},0),1) -> 41456
A22: Rural+Urban | B22: 2013 | C22: July | D22: 114.8 | E22: 116.4 | F22: 111.9 | G22: 108.9 | H22: 104.3 | I22: 111.7 | J22: 140 | K22: 106.4 | L22: 103.3 | M22: 106.8 | N22: 109.6 | O22: 112.6 | P22: 114.7 | Q22: 110.3 | R22: 110.2 | S22: 108.8 | T22: 110 | U22: 107.7 | V22: 109.2 | W22: 108.2 | X22: 107 | Y22: 107.1 | Z22: 106.1 | AA22: 109.1 | AB22: 102.8 | AC22: 106.9 | AD22: 111 | AE22: =tbl_CPI_Clean[[#This Row],[Sector]]&"_"&tbl_CPI_Clean[[#This Row],[Year]]&"_"&tbl_CPI_Clean[[#This Row],[Month]] -> Rural+Urban_2013_July | AF22: =DATE(tbl_CPI_Clean[[#This Row],[Year]],MATCH(tbl_CPI_Clean[[#This Row],[Month]],{"January","February","March","April","May","June","July","August","September","October","November","December"},0),1) -> 41456
A23: Rural | B23: 2013 | C23: August | D23: 114.3 | E23: 115.4 | F23: 111.1 | G23: 110 | H23: 106.4 | I23: 110.8 | J23: 138.9 | K23: 107.4 | L23: 104.1 | M23: 106.9 | N23: 109.7 | O23: 112.6 | P23: 114.9 | Q23: 110.7 | R23: 111.3 | S23: 110.2 | T23: 111.1 | U23: NA | V23: 109.9 | W23: 108.7 | X23: 107.5 | Y23: 107.8 | Z23: 106.8 | AA23: 108.7 | AB23: 105 | AC23: 107.5 | AD23: 112.1 | AE23: =tbl_CPI_Clean[[#This Row],[Sector]]&"_"&tbl_CPI_Clean[[#This Row],[Year]]&"_"&tbl_CPI_Clean[[#This Row],[Month]] -> Rural_2013_August | AF23: =DATE(tbl_CPI_Clean[[#This Row],[Year]],MATCH(tbl_CPI_Clean[[#This Row],[Month]],{"January","February","March","April","May","June","July","August","September","October","November","December"},0),1) -> 41487
A24: Urban | B24: 2013 | C24: August | D24: 118.3 | E24: 120.4 | F24: 112.7 | G24: 108.9 | H24: 101.1 | I24: 108.7 | J24: 177 | K24: 104.7 | L24: 101 | M24: 108.5 | N24: 110.9 | O24: 114.3 | P24: 119.6 | Q24: 112.4 | R24: 110.6 | S24: 108.3 | T24: 110.2 | U24: 108.9 | V24: 109.3 | W24: 108.7 | X24: 107.6 | Y24: 108.1 | Z24: 106.5 | AA24: 110.8 | AB24: 106 | AC24: 108.3 | AD24: 112.7 | AE24: =tbl_CPI_Clean[[#This Row],[Sector]]&"_"&tbl_CPI_Clean[[#This Row],[Year]]&"_"&tbl_CPI_Clean[[#This Row],[Month]] -> Urban_2013_August | AF24: =DATE(tbl_CPI_Clean[[#This Row],[Year]],MATCH(tbl_CPI_Clean[[#This Row],[Month]],{"January","February","March","April","May","June","July","August","September","October","November","December"},0),1) -> 41487
A25: Rural+Urban | B25: 2013 | C25: August | D25: 115.6 | E25: 117.2 | F25: 111.7 | G25: 109.6 | H25: 104.5 | I25: 109.8 | J25: 151.8 | K25: 106.5 | L25: 103.1 | M25: 107.4 | N25: 110.2 | O25: 113.4 | P25: 116.6 | Q25: 111.2 | R25: 111 | S25: 109.4 | T25: 110.7 | U25: 108.9 | V25: 109.7 | W25: 108.7 | X25: 107.5 | Y25: 108 | Z25: 106.6 | AA25: 109.9 | AB25: 105.4 | AC25: 107.9 | AD25: 112.4 | AE25: =tbl_CPI_Clean[[#This Row],[Sector]]&"_"&tbl_CPI_Clean[[#This Row],[Year]]&"_"&tbl_CPI_Clean[[#This Row],[Month]] -> Rural+Urban_2013_August | AF25: =DATE(tbl_CPI_Clean[[#This Row],[Year]],MATCH(tbl_CPI_Clean[[#This Row],[Month]],{"January","February","March","April","May","June","July","August","September","October","November","December"},0),1) -> 41487
A26: Rural | B26: 2013 | C26: September | D26: 115.4 | E26: 115.7 | F26: 111.7 | G26: 111 | H26: 107.4 | I26: 110.9 | J26: 154 | K26: 108.1 | L26: 104.2 | M26: 107.9 | N26: 110.4 | O26: 114 | P26: 117.8 | Q26: 111.7 | R26: 112.7 | S26: 111.4 | T26: 112.5 | U26: NA | V26: 111.1 | W26: 109.6 | X26: 108.3 | Y26: 109.3 | Z26: 107.7 | AA26: 109.8 | AB26: 106.7 | AC26: 108.7 | AD26: 114.2 | AE26: =tbl_CPI_Clean[[#This Row],[Sector]]&"_"&tbl_CPI_Clean[[#This Row],[Year]]&"_"&tbl_CPI_Clean[[#This Row],[Month]] -> Rural_2013_September | AF26: =DATE(tbl_CPI_Clean[[#This Row],[Year]],MATCH(tbl_CPI_Clean[[#This Row],[Month]],{"January","February","March","April","May","June","July","August","September","October","November","December"},0),1) -> 41518
A27: Urban | B27: 2013 | C27: September | D27: 118.6 | E27: 119.1 | F27: 113.2 | G27: 109.6 | H27: 101.7 | I27: 103.2 | J27: 174.3 | K27: 105.1 | L27: 100.8 | M27: 109.1 | N27: 111.1 | O27: 115.4 | P27: 119.2 | Q27: 112.9 | R27: 111.4 | S27: 109 | T27: 111.1 | U27: 109.7 | V27: 109.5 | W27: 109.6 | X27: 107.9 | Y27: 110.4 | Z27: 107.4 | AA27: 111.2 | AB27: 106.9 | AC27: 109.4 | AD27: 113.2 | AE27: =tbl_CPI_Clean[[#This Row],[Sector]]&"_"&tbl_CPI_Clean[[#This Row],[Year]]&"_"&tbl_CPI_Clean[[#This Row],[Month]] -> Urban_2013_September | AF27: =DATE(tbl_CPI_Clean[[#This Row],[Year]],MATCH(tbl_CPI_Clean[[#This Row],[Month]],{"January","February","March","April","May","June","July","August","September","October","November","December"},0),1) -> 41518
A28: Rural+Urban | B28: 2013 | C28: September | D28: 116.4 | E28: 116.9 | F28: 112.3 | G28: 110.5 | H28: 105.3 | I28: 107.3 | J28: 160.9 | K28: 107.1 | L28: 103.1 | M28: 108.3 | N28: 110.7 | O28: 114.6 | P28: 118.3 | Q28: 112 | R28: 112.2 | S28: 110.4 | T28: 111.9 | U28: 109.7 | V28: 110.5 | W28: 109.6 | X28: 108.1 | Y28: 109.9 | Z28: 107.5 | AA28: 110.6 | AB28: 106.8 | AC28: 109 | AD28: 113.7 | AE28: =tbl_CPI_Clean[[#This Row],[Sector]]&"_"&tbl_CPI_Clean[[#This Row],[Year]]&"_"&tbl_CPI_Clean[[#This Row],[Month]] -> Rural+Urban_2013_September | AF28: =DATE(tbl_CPI_Clean[[#This Row],[Year]],MATCH(tbl_CPI_Clean[[#This Row],[Month]],{"January","February","March","April","May","June","July","August","September","October","November","December"},0),1) -> 41518
A29: Rural | B29: 2013 | C29: October | D29: 116.3 | E29: 115.4 | F29: 112.6 | G29: 111.7 | H29: 107.7 | I29: 113.2 | J29: 164.9 | K29: 108.3 | L29: 103.9 | M29: 108.2 | N29: 111.1 | O29: 114.9 | P29: 119.8 | Q29: 112.2 | R29: 113.6 | S29: 112.3 | T29: 113.4 | U29: NA | V29: 111.6 | W29: 110.4 | X29: 108.9 | Y29: 109.3 | Z29: 108.3 | AA29: 110.2 | AB29: 107.5 | AC29: 109.1 | AD29: 115.5 | AE29: =tbl_CPI_Clean[[#This Row],[Sector]]&"_"&tbl_CPI_Clean[[#This Row],[Year]]&"_"&tbl_CPI_Clean[[#This Row],[Month]] -> Rural_2013_October | AF29: =DATE(tbl_CPI_Clean[[#This Row],[Year]],MATCH(tbl_CPI_Clean[[#This Row],[Month]],{"January","February","March","April","May","June","July","August","September","October","November","December"},0),1) -> 41548
A30: Urban | B30: 2013 | C30: October | D30: 118.9 | E30: 118.1 | F30: 114.5 | G30: 110.4 | H30: 102.3 | I30: 106.2 | J30: 183.5 | K30: 105.3 | L30: 100.2 | M30: 109.6 | N30: 111.4 | O30: 116 | P30: 120.8 | Q30: 113.5 | R30: 112.5 | S30: 109.7 | T30: 112 | U30: 110.5 | V30: 109.7 | W30: 110.2 | X30: 108.2 | Y30: 109.7 | Z30: 108 | AA30: 111.3 | AB30: 107.3 | AC30: 109.4 | AD30: 114 | AE30: =tbl_CPI_Clean[[#This Row],[Sector]]&"_"&tbl_CPI_Clean[[#This Row],[Year]]&"_"&tbl_CPI_Clean[[#This Row],[Month]] -> Urban_2013_October | AF30: =DATE(tbl_CPI_Clean[[#This Row],[Year]],MATCH(tbl_CPI_Clean[[#This Row],[Month]],{"January","February","March","April","May","June","July","August","September","October","November","December"},0),1) -> 41548
A31: Rural+Urban | B31: 2013 | C31: October | D31: 117.1 | E31: 116.3 | F31: 113.3 | G31: 111.2 | H31: 105.7 | I31: 109.9 | J31: 171.2 | K31: 107.3 | L31: 102.7 | M31: 108.7 | N31: 111.2 | O31: 115.4 | P31: 120.2 | Q31: 112.5 | R31: 113.2 | S31: 111.2 | T31: 112.8 | U31: 110.5 | V31: 110.9 | W31: 110.3 | X31: 108.6 | Y31: 109.5 | Z31: 108.1 | AA31: 110.8 | AB31: 107.4 | AC31: 109.2 | AD31: 114.8 | AE31: =tbl_CPI_Clean[[#This Row],[Sector]]&"_"&tbl_CPI_Clean[[#This Row],[Year]]&"_"&tbl_CPI_Clean[[#This Row],[Month]] -> Rural+Urban_2013_October | AF31: =DATE(tbl_CPI_Clean[[#This Row],[Year]],MATCH(tbl_CPI_Clean[[#This Row],[Month]],{"January","February","March","April","May","June","July","August","September","October","November","December"},0),1) -> 41548
A32: Rural | B32: 2013 | C32: November | D32: 117.3 | E32: 114.9 | F32: 116.2 | G32: 112.8 | H32: 108.9 | I32: 116.6 | J32: 178.1 | K32: 109.1 | L32: 103.6 | M32: 109 | N32: 111.8 | O32: 116 | P32: 122.5 | Q32: 112.8 | R32: 114.6 | S32: 113.1 | T32: 114.4 | U32: NA | V32: 112.6 | W32: 111.3 | X32: 109.7 | Y32: 109.6 | Z32: 108.7 | AA32: 111 | AB32: 108.2 | AC32: 109.8 | AD32: 117.4 | AE32: =tbl_CPI_Clean[[#This Row],[Sector]]&"_"&tbl_CPI_Clean[[#This Row],[Year]]&"_"&tbl_CPI_Clean[[#This Row],[Month]] -> Rural_2013_November | AF32: 41579
A33: Urban | B33: 2013 | C33: November | D33: 119.8 | E33: 116.3 | F33: 122.6 | G33: 112 | H33: 103.2 | I33: 110 | J33: 192.8 | K33: 106.3 | L33: 99.5 | M33: 110.3 | N33: 111.8 | O33: 117.1 | P33: 122.9 | Q33: 114.1 | R33: 113.5 | S33: 110.3 | T33: 113 | U33: 111.1 | V33: 110 | W33: 110.9 | X33: 108.6 | Y33: 109.5 | Z33: 108.5 | AA33: 111.3 | AB33: 107.9 | AC33: 109.6 | AD33: 115 | AE33: =tbl_CPI_Clean[[#This Row],[Sector]]&"_"&tbl_CPI_Clean[[#This Row],[Year]]&"_"&tbl_CPI_Clean[[#This Row],[Month]] -> Urban_2013_November | AF33: =DATE(tbl_CPI_Clean[[#This Row],[Year]],MATCH(tbl_CPI_Clean[[#This Row],[Month]],{"January","February","March","April","May","June","July","August","September","October","November","December"},0),1) -> 41579
A34: Rural+Urban | B34: 2013 | C34: November | D34: 118.1 | E34: 115.4 | F34: 118.7 | G34: 112.5 | H34: 106.8 | I34: 113.5 | J34: 183.1 | K34: 108.2 | L34: 102.2 | M34: 109.4 | N34: 111.8 | O34: 116.5 | P34: 122.6 | Q34: 113.1 | R34: 114.2 | S34: 111.9 | T34: 113.8 | U34: 111.1 | V34: 111.6 | W34: 111.1 | X34: 109.3 | Y34: 109.5 | Z34: 108.6 | AA34: 111.2 | AB34: 108.1 | AC34: 109.7 | AD34: 116.3 | AE34: =tbl_CPI_Clean[[#This Row],[Sector]]&"_"&tbl_CPI_Clean[[#This Row],[Year]]&"_"&tbl_CPI_Clean[[#This Row],[Month]] -> Rural+Urban_2013_November | AF34: =DATE(tbl_CPI_Clean[[#This Row],[Year]],MATCH(tbl_CPI_Clean[[#This Row],[Month]],{"January","February","March","April","May","June","July","August","September","October","November","December"},0),1) -> 41579
A35: Rural | B35: 2013 | C35: December | D35: 118.4 | E35: 115.9 | F35: 120.4 | G35: 113.8 | H35: 109.5 | I35: 115.5 | J35: 145.7 | K35: 109.5 | L35: 102.9 | M35: 109.8 | N35: 112.1 | O35: 116.8 | P35: 118.7 | Q35: 113.6 | R35: 115.8 | S35: 114 | T35: 115.5 | U35: NA | V35: 112.8 | W35: 112.1 | X35: 110.1 | Y35: 109.9 | Z35: 109.2 | AA35: 111.6 | AB35: 108.1 | AC35: 110.1 | AD35: 115.5 | AE35: =tbl_CPI_Clean[[#This Row],[Sector]]&"_"&tbl_CPI_Clean[[#This Row],[Year]]&"_"&tbl_CPI_Clean[[#This Row],[Month]] -> Rural_2013_December | AF35: =DATE(tbl_CPI_Clean[[#This Row],[Year]],MATCH(tbl_CPI_Clean[[#This Row],[Month]],{"January","February","March","April","May","June","July","August","September","October","November","December"},0),1) -> 41609
A36: Urban | B36: 2013 | C36: December | D36: 120.5 | E36: 118.1 | F36: 128.5 | G36: 112.8 | H36: 103.4 | I36: 110.7 | J36: 144.8 | K36: 107.1 | L36: 98.6 | M36: 111.9 | N36: 112.1 | O36: 118.1 | P36: 117.8 | Q36: 115 | R36: 114.2 | S36: 110.9 | T36: 113.7 | U36: 110.7 | V36: 110.4 | W36: 111.3 | X36: 109 | Y36: 109.7 | Z36: 108.9 | AA36: 111.4 | AB36: 107.7 | AC36: 109.8 | AD36: 113.3 | AE36: =tbl_CPI_Clean[[#This Row],[Sector]]&"_"&tbl_CPI_Clean[[#This Row],[Year]]&"_"&tbl_CPI_Clean[[#This Row],[Month]] -> Urban_2013_December | AF36: =DATE(tbl_CPI_Clean[[#This Row],[Year]],MATCH(tbl_CPI_Clean[[#This Row],[Month]],{"January","February","March","April","May","June","July","August","September","October","November","December"},0),1) -> 41609
A37: Rural+Urban | B37: 2013 | C37: December | D37: 119.1 | E37: 116.7 | F37: 123.5 | G37: 113.4 | H37: 107.3 | I37: 113.3 | J37: 145.4 | K37: 108.7 | L37: 101.5 | M37: 110.5 | N37: 112.1 | O37: 117.4 | P37: 118.4 | Q37: 114 | R37: 115.2 | S37: 112.7 | T37: 114.8 | U37: 110.7 | V37: 111.9 | W37: 111.7 | X37: 109.7 | Y37: 109.8 | Z37: 109 | AA37: 111.5 | AB37: 107.9 | AC37: 110 | AD37: 114.5 | AE37: =tbl_CPI_Clean[[#This Row],[Sector]]&"_"&tbl_CPI_Clean[[#This Row],[Year]]&"_"&tbl_CPI_Clean[[#This Row],[Month]] -> Rural+Urban_2013_December | AF37: =DATE(tbl_CPI_Clean[[#This Row],[Year]],MATCH(tbl_CPI_Clean[[#This Row],[Month]],{"January","February","March","April","May","June","July","August","September","October","November","December"},0),1) -> 41609
A38: Rural | B38: 2014 | C38: January | D38: 118.9 | E38: 117.1 | F38: 120.5 | G38: 114.4 | H38: 109 | I38: 115.5 | J38: 123.9 | K38: 109.6 | L38: 101.8 | M38: 110.2 | N38: 112.4 | O38: 117.3 | P38: 116 | Q38: 114 | R38: 116.5 | S38: 114.5 | T38: 116.2 | U38: NA | V38: 113 | W38: 112.6 | X38: 110.6 | Y38: 110.5 | Z38: 109.6 | AA38: 111.8 | AB38: 108.3 | AC38: 110.6 | AD38: 114.2 | AE38: =tbl_CPI_Clean[[#This Row],[Sector]]&"_"&tbl_CPI_Clean[[#This Row],[Year]]&"_"&tbl_CPI_Clean[[#This Row],[Month]] -> Rural_2014_January | AF38: =DATE(tbl_CPI_Clean[[#This Row],[Year]],MATCH(tbl_CPI_Clean[[#This Row],[Month]],{"January","February","March","April","May","June","July","August","September","October","November","December"},0),1) -> 41640
A39: Urban | B39: 2014 | C39: January | D39: 121.2 | E39: 122 | F39: 129.9 | G39: 113.6 | H39: 102.9 | I39: 112.1 | J39: 118.9 | K39: 107.5 | L39: 96.9 | M39: 112.7 | N39: 112.1 | O39: 119 | P39: 115.5 | Q39: 115.7 | R39: 114.8 | S39: 111.3 | T39: 114.3 | U39: 111.6 | V39: 111 | W39: 111.9 | X39: 109.7 | Y39: 110.8 | Z39: 109.8 | AA39: 111.5 | AB39: 108 | AC39: 110.5 | AD39: 112.9 | AE39: =tbl_CPI_Clean[[#This Row],[Sector]]&"_"&tbl_CPI_Clean[[#This Row],[Year]]&"_"&tbl_CPI_Clean[[#This Row],[Month]] -> Urban_2014_January | AF39: =DATE(tbl_CPI_Clean[[#This Row],[Year]],MATCH(tbl_CPI_Clean[[#This Row],[Month]],{"January","February","March","April","May","June","July","August","September","October","November","December"},0),1) -> 41640
A40: Rural+Urban | B40: 2014 | C40: January | D40: 119.6 | E40: 118.8 | F40: 124.1 | G40: 114.1 | H40: 106.8 | I40: 113.9 | J40: 122.2 | K40: 108.9 | L40: 100.2 | M40: 111 | N40: 112.3 | O40: 118.1 | P40: 115.8 | Q40: 114.5 | R40: 115.8 | S40: 113.2 | T40: 115.4 | U40: 111.6 | V40: 112.2 | W40: 112.3 | X40: 110.3 | Y40: 110.7 | Z40: 109.7 | AA40: 111.6 | AB40: 108.2 | AC40: 110.6 | AD40: 113.6 | AE40: =tbl_CPI_Clean[[#This Row],[Sector]]&"_"&tbl_CPI_Clean[[#This Row],[Year]]&"_"&tbl_CPI_Clean[[#This Row],[Month]] -> Rural+Urban_2014_January | AF40: =DATE(tbl_CPI_Clean[[#This Row],[Year]],MATCH(tbl_CPI_Clean[[#This Row],[Month]],{"January","February","March","April","May","June","July","August","September","October","November","December"},0),1) -> 41640
...

Sheet 03_Q1_Contribution
A1: Question 1 - Calculate the contribution of broader CPI categories to the overall CPI for May 2023.
A3: Broader Category | B3: Index Value | C3: Contribution %
A4: Food | B4: =AVERAGEIFS(tbl_CPI_Clean[Food and beverages],tbl_CPI_Clean[Year],2023,tbl_CPI_Clean[Month],"May",tbl_CPI_Clean[Sector],"Rural+Urban") -> 179.1 | C4: =B4/SUM($B$4:$B$15) -> 0.082932024
A5: Fuel & Light | B5: =AVERAGEIFS(tbl_CPI_Clean[Fuel and light],tbl_CPI_Clean[Year],2023,tbl_CPI_Clean[Month],"May",tbl_CPI_Clean[Sector],"Rural+Urban") -> 182.8 | C5: =B5/SUM($B$4:$B$15) -> 0.084645305
A6: Clothing & Footwear | B6: =AVERAGEIFS(tbl_CPI_Clean[Clothing and footwear],tbl_CPI_Clean[Year],2023,tbl_CPI_Clean[Month],"May",tbl_CPI_Clean[Sector],"Rural+Urban") -> 186.2 | C6: =B6/SUM($B$4:$B$15) -> 0.08621967
A7: Housing | B7: =AVERAGEIFS(tbl_CPI_Clean[Housing],tbl_CPI_Clean[Year],2023,tbl_CPI_Clean[Month],"May",tbl_CPI_Clean[Sector],"Rural+Urban") -> 175.6 | C7: =B7/SUM($B$4:$B$15) -> 0.081311354
A8: Household Goods & Services | B8: =AVERAGEIFS(tbl_CPI_Clean[Household goods and services],tbl_CPI_Clean[Year],2023,tbl_CPI_Clean[Month],"May",tbl_CPI_Clean[Sector],"Rural+Urban") -> 175.2 | C8: =B8/SUM($B$4:$B$15) -> 0.081126134
A9: Health | B9: =AVERAGEIFS(tbl_CPI_Clean[Health],tbl_CPI_Clean[Year],2023,tbl_CPI_Clean[Month],"May",tbl_CPI_Clean[Sector],"Rural+Urban") -> 185.7 | C9: =B9/SUM($B$4:$B$15) -> 0.085988146
A10: Transport & Communication | B10: =AVERAGEIFS(tbl_CPI_Clean[Transport and communication],tbl_CPI_Clean[Year],2023,tbl_CPI_Clean[Month],"May",tbl_CPI_Clean[Sector],"Rural+Urban") -> 164.8 | C10: =B10/SUM($B$4:$B$15) -> 0.076310428
A11: Recreation & Amusement | B11: =AVERAGEIFS(tbl_CPI_Clean[Recreation and amusement],tbl_CPI_Clean[Year],2023,tbl_CPI_Clean[Month],"May",tbl_CPI_Clean[Sector],"Rural+Urban") -> 171.2 | C11: =B11/SUM($B$4:$B$15) -> 0.07927394
A12: Education | B12: =AVERAGEIFS(tbl_CPI_Clean[Education],tbl_CPI_Clean[Year],2023,tbl_CPI_Clean[Month],"May",tbl_CPI_Clean[Sector],"Rural+Urban") -> 177.1 | C12: =B12/SUM($B$4:$B$15) -> 0.082005927
A13: Personal Care & Effects | B13: =AVERAGEIFS(tbl_CPI_Clean[Personal care and effects],tbl_CPI_Clean[Year],2023,tbl_CPI_Clean[Month],"May",tbl_CPI_Clean[Sector],"Rural+Urban") -> 185.2 | C13: =B13/SUM($B$4:$B$15) -> 0.085756622
A14: Miscellaneous | B14: =AVERAGEIFS(tbl_CPI_Clean[Miscellaneous],tbl_CPI_Clean[Year],2023,tbl_CPI_Clean[Month],"May",tbl_CPI_Clean[Sector],"Rural+Urban") -> 175.7 | C14: =B14/SUM($B$4:$B$15) -> 0.081357659
A15: Pan, Tobacco & Intoxicants | B15: =AVERAGEIFS(tbl_CPI_Clean[Pan, tobacco and intoxicants],tbl_CPI_Clean[Year],2023,tbl_CPI_Clean[Month],"May",tbl_CPI_Clean[Sector],"Rural+Urban") -> 201 | C15: =B15/SUM($B$4:$B$15) -> 0.093072791
A19: Highest Contribution
A20: Pan, Tobacco & Intoxicants — 9.31%
A25: In May 2023, Pan, Tobacco & Intoxicants contributed the highest share (9.31%) to CPI, followed closely by Clothing & Footwear, Health, and Personal Care. Food remained a significant contributor at 8.29%, highlighting its continued importance in inflation measurement.

Sheet 04_Q2_YoY_Trend
A1: Question 2 - YoY trend (2017 onwards)
A4: Year | B4: General Index (Jan) | C4: Genaral Index(Last Month) | D4: YoY Inflation %
A5: 2017 | B5: {=INDEX('02_Clean_Data'!$AD:$AD, MATCH(1, ('02_Clean_Data'!$B:$B=2017)*('02_Clean_Data'!$A:$A ="Rural+Urban")*('02_Clean_Data'!$C:$C="January"),0))} -> 130.3 | C5: {=INDEX('02_Clean_Data'!$AD:$AD, MATCH(1, ('02_Clean_Data'!$B:$B=2017)*('02_Clean_Data'!$A:$A ="Rural+Urban")*('02_Clean_Data'!$C:$C="December"),0))} -> 137.2 | D5: =(C5-B5)/B5 -> 0.05295472
A6: 2018 | B6: {=INDEX('02_Clean_Data'!$AD:$AD, MATCH(1, ('02_Clean_Data'!$B:$B=2018)*('02_Clean_Data'!$A:$A ="Rural+Urban")*('02_Clean_Data'!$C:$C="January"),0))} -> 136.9 | C6: {=INDEX('02_Clean_Data'!$AD:$AD, MATCH(1, ('02_Clean_Data'!$B:$B=2018)*('02_Clean_Data'!$A:$A ="Rural+Urban")*('02_Clean_Data'!$C:$C="December"),0))} -> 140.1 | D6: =(C6-B6)/B6 -> 0.023374726
A7: 2019 | B7: {=INDEX('02_Clean_Data'!$AD:$AD, MATCH(1, ('02_Clean_Data'!$B:$B=2019)*('02_Clean_Data'!$A:$A ="Rural+Urban")*('02_Clean_Data'!$C:$C="January"),0))} -> 139.6 | C7: {=INDEX('02_Clean_Data'!$AD:$AD, MATCH(1, ('02_Clean_Data'!$B:$B=2019)*('02_Clean_Data'!$A:$A ="Rural+Urban")*('02_Clean_Data'!$C:$C="December"),0))} -> 150.4 | D7: =(C7-B7)/B7 -> 0.077363897
A8: 2020 | B8: {=INDEX('02_Clean_Data'!$AD:$AD, MATCH(1, ('02_Clean_Data'!$B:$B=2020)*('02_Clean_Data'!$A:$A ="Rural+Urban")*('02_Clean_Data'!$C:$C="January"),0))} -> 150.2 | C8: {=INDEX('02_Clean_Data'!$AD:$AD, MATCH(1, ('02_Clean_Data'!$B:$B=2020)*('02_Clean_Data'!$A:$A ="Rural+Urban")*('02_Clean_Data'!$C:$C="December"),0))} -> 158.9 | D8: =(C8-B8)/B8 -> 0.05792277
A9: 2021 | B9: {=INDEX('02_Clean_Data'!$AD:$AD, MATCH(1, ('02_Clean_Data'!$B:$B=2021)*('02_Clean_Data'!$A:$A ="Rural+Urban")*('02_Clean_Data'!$C:$C="January"),0))} -> 157.3 | C9: {=INDEX('02_Clean_Data'!$AD:$AD, MATCH(1, ('02_Clean_Data'!$B:$B=2021)*('02_Clean_Data'!$A:$A ="Rural+Urban")*('02_Clean_Data'!$C:$C="December"),0))} -> 166.2 | D9: =(C9-B9)/B9 -> 0.056579784
A10: 2022 | B10: {=INDEX('02_Clean_Data'!$AD:$AD, MATCH(1, ('02_Clean_Data'!$B:$B=2022)*('02_Clean_Data'!$A:$A ="Rural+Urban")*('02_Clean_Data'!$C:$C="January"),0))} -> 165.7 | C10: {=INDEX('02_Clean_Data'!$AD:$AD, MATCH(1, ('02_Clean_Data'!$B:$B=2022)*('02_Clean_Data'!$A:$A ="Rural+Urban")*('02_Clean_Data'!$C:$C="December"),0))} -> 175.7 | D10: =(C10-B10)/B10 -> 0.06035003
A11: 2023 | B11: {=INDEX('02_Clean_Data'!$AD:$AD, MATCH(1, ('02_Clean_Data'!$B:$B=2023)*('02_Clean_Data'!$A:$A ="Rural+Urban")*('02_Clean_Data'!$C:$C="January"),0))} -> 176.5 | C11: {=INDEX('02_Clean_Data'!$AD:$AD, MATCH(1, ('02_Clean_Data'!$B:$B=2023)*('02_Clean_Data'!$A:$A ="Rural+Urban")*('02_Clean_Data'!$C:$C="May"),0))} -> 179.1 | D11: =(C11-B11)/B11 -> 0.014730878

Sheet 05_Q3_Monthly_Trend
A1: Question 3 - Monthly Trend
A5: Month | B5: Food index | C5: MoM Inflation % | E5: Row Labels | F5: Average of Food and beverages | H5: Category | I5: June(2022) | J5: May(2023) | K5: Absolute Change
A6: 44713 | B6: 175.53333 | E6: 44713 | F6: 175.53333 | H6: Cereals and products | I6: =AVERAGEIFS('02_Clean_Data'!D:D,'02_Clean_Data'!B:B,2022,'02_Clean_Data'!C:C,"June") -> 155.43333 | J6: =AVERAGEIFS('02_Clean_Data'!D:D,'02_Clean_Data'!B:B,2023,'02_Clean_Data'!C:C,"May") -> 173.86667 | K6: =J6-I6 -> 18.433333
A7: 44743 | B7: 175.63333 | C7: =(B7-B6)/B6 -> 0.00056969237 | E7: 44743 | F7: 175.63333 | H7: Meat and fish | I7: =AVERAGEIFS('02_Clean_Data'!E:E,'02_Clean_Data'!B:B,2022,'02_Clean_Data'!C:C,"June") -> 220 | J7: =AVERAGEIFS('02_Clean_Data'!E:E,'02_Clean_Data'!B:B,2023,'02_Clean_Data'!C:C,"May") -> 215.06667 | K7: =J7-I7 -> -4.9333333
A8: 44774 | B8: 176.86667 | C8: =(B8-B7)/B7 -> 0.0070222054 | E8: 44774 | F8: 176.86667 | H8: Egg | I8: =AVERAGEIFS('02_Clean_Data'!F:F,'02_Clean_Data'!B:B,2022,'02_Clean_Data'!C:C,"June") -> 171.06667 | J8: =AVERAGEIFS('02_Clean_Data'!F:F,'02_Clean_Data'!B:B,2023,'02_Clean_Data'!C:C,"May") -> 173.63333 | K8: =J8-I8 -> 2.5666667
A9: 44805 | B9: 178.36667 | C9: =(B9-B8)/B8 -> 0.0084809649 | E9: 44805 | F9: 178.36667 | H9: Milk and products | I9: =AVERAGEIFS('02_Clean_Data'!G:G,'02_Clean_Data'!B:B,2022,'02_Clean_Data'!C:C,"June") -> 165.86667 | J9: =AVERAGEIFS('02_Clean_Data'!G:G,'02_Clean_Data'!B:B,2023,'02_Clean_Data'!C:C,"May") -> 179.5 | K9: =J9-I9 -> 13.633333
A10: 44835 | B10: 180.1 | C10: =(B10-B9)/B9 -> 0.0097178098 | E10: 44835 | F10: 180.1 | H10: Oils and fats | I10: =AVERAGEIFS('02_Clean_Data'!H:H,'02_Clean_Data'!B:B,2022,'02_Clean_Data'!C:C,"June") -> 199.2 | J10: =AVERAGEIFS('02_Clean_Data'!H:H,'02_Clean_Data'!B:B,2023,'02_Clean_Data'!C:C,"May") -> 169.23333 | K10: =J10-I10 -> -29.966667
A11: 44866 | B11: 178.73333 | C11: =(B11-B10)/B10 -> -0.0075883768 | E11: 44866 | F11: 178.73333 | H11: Fruits | I11: =AVERAGEIFS('02_Clean_Data'!I:I,'02_Clean_Data'!B:B,2022,'02_Clean_Data'!C:C,"June") -> 169.86667 | J11: =AVERAGEIFS('02_Clean_Data'!I:I,'02_Clean_Data'!B:B,2023,'02_Clean_Data'!C:C,"May") -> 172.33333 | K11: =J11-I11 -> 2.4666667
A12: 44896 | B12: 176.3 | C12: =(B12-B11)/B11 -> -0.013614323 | E12: 44896 | F12: 176.3 | H12: Vegetables | I12: =AVERAGEIFS('02_Clean_Data'!J:J,'02_Clean_Data'!B:B,2022,'02_Clean_Data'!C:C,"June") -> 187.03333 | J12: =AVERAGEIFS('02_Clean_Data'!J:J,'02_Clean_Data'!B:B,2023,'02_Clean_Data'!C:C,"May") -> 164.9 | K12: =J12-I12 -> -22.133333
A13: 44927 | B13: 177.06667 | C13: =(B13-B12)/B12 -> 0.0043486481 | E13: 44927 | F13: 177.06667 | H13: Pulses and products | I13: =AVERAGEIFS('02_Clean_Data'!K:K,'02_Clean_Data'!B:B,2022,'02_Clean_Data'!C:C,"June") -> 164.16667 | J13: =AVERAGEIFS('02_Clean_Data'!K:K,'02_Clean_Data'!B:B,2023,'02_Clean_Data'!C:C,"May") -> 175.8 | K13: =J13-I13 -> 11.633333
A14: 44958 | B14: 177.5 | C14: =(B14-B13)/B13 -> 0.0024472892 | E14: 44958 | F14: 177.5 | H14: Sugar and Confectionery | I14: =AVERAGEIFS('02_Clean_Data'!L:L,'02_Clean_Data'!B:B,2022,'02_Clean_Data'!C:C,"June") -> 120.13333 | J14: =AVERAGEIFS('02_Clean_Data'!L:L,'02_Clean_Data'!B:B,2023,'02_Clean_Data'!C:C,"May") -> 122.93333 | K14: =J14-I14 -> 2.8
A15: 44986 | B15: 177.53333 | C15: =(B15-B14)/B14 -> 0.00018779343 | E15: 44986 | F15: 177.53333 | H15: Spices | I15: =AVERAGEIFS('02_Clean_Data'!M:M,'02_Clean_Data'!B:B,2022,'02_Clean_Data'!C:C,"June") -> 186.5 | J15: =AVERAGEIFS('02_Clean_Data'!M:M,'02_Clean_Data'!B:B,2023,'02_Clean_Data'!C:C,"May") -> 216.96667 | K15: =J15-I15 -> 30.466667
A16: 45017 | B16: 178.5 | C16: =(B16-B15)/B15 -> 0.0054449869 | E16: 45017 | F16: 178.5 | H16: Non-alcoholic beverages | I16: =AVERAGEIFS('02_Clean_Data'!N:N,'02_Clean_Data'!B:B,2022,'02_Clean_Data'!C:C,"June") -> 167.06667 | J16: =AVERAGEIFS('02_Clean_Data'!N:N,'02_Clean_Data'!B:B,2023,'02_Clean_Data'!C:C,"May") -> 172.66667 | K16: =J16-I16 -> 5.6
A17: 45047 | B17: 179.66667 | C17: =(B17-B16)/B16 -> 0.0065359477 | E17: 45047 | F17: 179.66667 | H17: Prepared meals, snacks, sweets etc. | I17: =AVERAGEIFS('02_Clean_Data'!O:O,'02_Clean_Data'!B:B,2022,'02_Clean_Data'!C:C,"June") -> 184.03333 | J17: =AVERAGEIFS('02_Clean_Data'!O:O,'02_Clean_Data'!B:B,2023,'02_Clean_Data'!C:C,"May") -> 194.33333 | K17: =J17-I17 -> 10.3
E18: Grand Total | F18: 177.65
A19: Grand Total | C19: =SUM(C7:C17) -> 0.023552638 | H19: Biggest Absolute Change - Spices(30.47)
H21: Highest Category | I21: =INDEX(H6:H17,MATCH(MAX(K6:K17),K6:K17,0)) -> Spices
H22: Lowest Category | I22: =INDEX(H6:H17,MATCH(MIN(K6:K17),K6:K17,0)) -> Oils and fats
H23: Highest Food Inflation Month | I23: =INDEX(A7:A17,MATCH(MAX(C7:C17),C7:C17,0)) -> 44835
H24: Lowest Food Inflation Month | I24: =INDEX(A7:A17,MATCH(MIN(C7:C17),C7:C17,0)) -> 44896
H25: Absolute Change in overall Food Index | I25: =B17-B6 -> 4.1333333

Sheet 06_Q4_COVID_Impact
A1: Question 4 - COVID Impact
A5: Month | B5: Food Index | C5: Health Index | D5: Fuel & light | E5: Transport & communication | F5: General Index | G5: Food MoM % | H5: Health MoM % | I5: Fuel MoM % | J5: Transport MoM % | K5: General MoM % | L5: COVID Phase | M5: Relative Month | O5: Relative Month | P5: Food MoM % | Q5: Health MoM % | R5: Fuel MoM % | S5: Transport MoM % | T5: General MoM %
A6: 43466 | B6: {=_xlfn.XLOOKUP(1,('02_Clean_Data'!$A:$A="Rural+Urban")*('02_Clean_Data'!$B:$B=YEAR(A6))*('02_Clean_Data'!$C:$C=TEXT(A6,"mmmm")),'02_Clean_Data'!$P:$P)} -> 137.4 | C6: {=_xlfn.XLOOKUP(1,('02_Clean_Data'!$A:$A="Rural+Urban")*('02_Clean_Data'!$B:$B=YEAR(A6))*('02_Clean_Data'!$C:$C=TEXT(A6,"mmmm")),'02_Clean_Data'!$X:$X)} -> 145.1 | D6: {=_xlfn.XLOOKUP(1,('02_Clean_Data'!$A:$A="Rural+Urban")*('02_Clean_Data'!$B:$B=YEAR(A6))*('02_Clean_Data'!$C:$C=TEXT(A6,"mmmm")),'02_Clean_Data'!$V:$V)} -> 139.5 | E6: {=_xlfn.XLOOKUP(1,('02_Clean_Data'!$A:$A="Rural+Urban")*('02_Clean_Data'!$B:$B=YEAR(A6))*('02_Clean_Data'!$C:$C=TEXT(A6,"mmmm")),'02_Clean_Data'!$Y:$Y)} -> 123.3 | F6: {=_xlfn.XLOOKUP(1,('02_Clean_Data'!$A:$A="Rural+Urban")*('02_Clean_Data'!$B:$B=YEAR(A6))*('02_Clean_Data'!$C:$C=TEXT(A6,"mmmm")),'02_Clean_Data'!$AD:$AD)} -> 139.6 | L6: =IF(A6=DATE(2020,3,1),"COVID Onset",IF(A6<DATE(2020,3,1),"Before COVID","After COVID")) -> Before COVID | M6: =(YEAR(A6)-2020)*12+MONTH(A6)-3 -> -14 | O6: =M6 -> -14 | P6: =_xlfn.XLOOKUP(O6,$M$6:$M$29,$G$6:$G$29,"NA") -> 0 | Q6: =_xlfn.XLOOKUP(O6,$M$6:$M$29,$H$6:$H$29,"NA") -> 0 | R6: =_xlfn.XLOOKUP(O6,$M$6:$M$29,$I$6:$I$29,"NA") -> 0 | S6: =_xlfn.XLOOKUP(O6,$M$6:$M$29,$J$6:$J$29,"NA") -> 0 | T6: =_xlfn.XLOOKUP(O6,$M$6:$M$29,$K$6:$K$29,"NA") -> 0
A7: 43497 | B7: {=_xlfn.XLOOKUP(1,('02_Clean_Data'!$A:$A="Rural+Urban")*('02_Clean_Data'!$B:$B=YEAR(A7))*('02_Clean_Data'!$C:$C=TEXT(A7,"mmmm")),'02_Clean_Data'!$P:$P)} -> 137.5 | C7: {=_xlfn.XLOOKUP(1,('02_Clean_Data'!$A:$A="Rural+Urban")*('02_Clean_Data'!$B:$B=YEAR(A7))*('02_Clean_Data'!$C:$C=TEXT(A7,"mmmm")),'02_Clean_Data'!$X:$X)} -> 145.6 | D7: {=_xlfn.XLOOKUP(1,('02_Clean_Data'!$A:$A="Rural+Urban")*('02_Clean_Data'!$B:$B=YEAR(A7))*('02_Clean_Data'!$C:$C=TEXT(A7,"mmmm")),'02_Clean_Data'!$V:$V)} -> 138.4 | E7: {=_xlfn.XLOOKUP(1,('02_Clean_Data'!$A:$A="Rural+Urban")*('02_Clean_Data'!$B:$B=YEAR(A7))*('02_Clean_Data'!$C:$C=TEXT(A7,"mmmm")),'02_Clean_Data'!$Y:$Y)} -> 123.9 | F7: {=_xlfn.XLOOKUP(1,('02_Clean_Data'!$A:$A="Rural+Urban")*('02_Clean_Data'!$B:$B=YEAR(A7))*('02_Clean_Data'!$C:$C=TEXT(A7,"mmmm")),'02_Clean_Data'!$AD:$AD)} -> 139.9 | G7: =IF(OR(B7="NA",B6="NA"),"NA",(B7-B6)/B6) -> 0.00072780204 | H7: =IF(OR(C7="NA",C6="NA"),"NA",(C7-C6)/C6) -> 0.0034458994 | I7: =IF(OR(D7="NA",D6="NA"),"NA",(D7-D6)/D6) -> -0.0078853047 | J7: =IF(OR(E7="NA",E6="NA"),"NA",(E7-E6)/E6) -> 0.00486618 | K7: =IF(OR(F7="NA",F6="NA"),"NA",(F7-F6)/F6) -> 0.0021489971 | L7: =IF(A7=DATE(2020,3,1),"COVID Onset",IF(A7<DATE(2020,3,1),"Before COVID","After COVID")) -> Before COVID | M7: =(YEAR(A7)-2020)*12+MONTH(A7)-3 -> -13 | O7: =M7 -> -13 | P7: =_xlfn.XLOOKUP(O7,$M$6:$M$29,$G$6:$G$29,"NA") -> 0.00072780204 | Q7: =_xlfn.XLOOKUP(O7,$M$6:$M$29,$H$6:$H$29,"NA") -> 0.0034458994 | R7: =_xlfn.XLOOKUP(O7,$M$6:$M$29,$I$6:$I$29,"NA") -> -0.0078853047 | S7: =_xlfn.XLOOKUP(O7,$M$6:$M$29,$J$6:$J$29,"NA") -> 0.00486618 | T7: =_xlfn.XLOOKUP(O7,$M$6:$M$29,$K$6:$K$29,"NA") -> 0.0021489971
